Workbook

Sheet 📋 Vue d'ensemble
A1: Référentiel d'accompagnement DevOps
A2: 205 actions d'accompagnement réparties sur 8 axes et 43 questions
A4: Stats globales
A5: Total actions | B5: =COUNTA('🎯 205 Actions'!A2:A300)-COUNTBLANK('🎯 205 Actions'!A2:A300) -> 111
A6: Questions couvertes | B6: =SUMPRODUCT(1/COUNTIF('🎯 205 Actions'!B2:B206,'🎯 205 Actions'!B2:B206)) -> 43
A7: Axes couverts | B7: =SUMPRODUCT(1/COUNTIF('🎯 205 Actions'!C2:C206,'🎯 205 Actions'!C2:C206)) -> 8
A8: Ateliers à écrire | B8: =COUNTIF('🎯 205 Actions'!K2:K206,"À écrire") -> 205
A9: Ateliers écrits | B9: =COUNTIF('🎯 205 Actions'!K2:K206,"Écrit") -> 0
A10: % Avancement | B10: =IFERROR(B9/B5,0) -> 0
A12: Comment lire ce référentiel
A13: Onglet 🎯 205 Actions | B13: Catalogue complet de toutes les actions, filtrable et triable.
A14: Onglet 📊 Par axe | B14: Synthèse par axe — combien d'actions, combien d'ateliers écrits.
A15: Onglet 🚦 Par priorité | B15: Vue par priorité (Haute/Moyenne/Basse/Préalable) pour planifier.
A16: Onglet 📝 Backlog Phase 1 | B16: Top 30-50 actions à écrire en priorité (à remplir avec données LCL).
A18: Statut 'À écrire' | B18: Atelier pas encore rédigé.
A19: Statut 'En cours' | B19: Atelier en rédaction (mets ton nom dans 'Assigné').
A20: Statut 'Écrit' | B20: Atelier rédigé, prêt pour review.
A21: Statut 'Validé' | B21: Atelier reviewé et publié.

Sheet 🎯 205 Actions
A1: # | B1: Question ID | C1: Axe | D1: Question | E1: Type | F1: Niveau | G1: Priorité | H1: Titre du niveau | I1: Action | J1: Métrique GitLab | K1: Statut atelier | L1: Assigné | M1: Notes | N1: Verdict coach | O1: Avis coach | P1: Action optimale ? (coach) | Q1: Ordre de production (coach)
A2: 1 | B2: C01 | C2: Culture & Rituels | D2: La squad dispose-t-elle de rituels communs entre Dev, Ops et autres parties prenantes ? | E2: Atelier | F2: Initial 🔴 | G2: Haute | H2: Aucun rituel commun | I2: Atelier "Notre premier daily" : accompagner la squad à instaurer un daily standup de 15 min max avec Dev + Ops | J2: — | K2: À écrire | N2: ✓ Bon | O2: Sensibilisation + 1er geste concret : gradation cohérente avec le niveau. | P2: 🔁 Daily défendable, mais pour une squad sans aucun rituel, tenter d'abord une rétro blameless : construit le muscle de collaboration et fait remonter la douleur (le daily glisse vite vers le statut). À jauger selon la maturité relationnelle. | Q2: V4 · Rituels communs Dev/Ops
A3: 2 | B3: C01 | C3: Culture & Rituels | D3: La squad dispose-t-elle de rituels communs entre Dev, Ops et autres parties prenantes ? | E3: Atelier | F3: Initial 🔴 | G3: Haute | H3: Aucun rituel commun | I3: Session "Pourquoi des rituels ?" : faire comprendre ensemble la valeur des rituels comme ciment de la collaboration | J3: — | K3: À écrire | N3: ✓ Bon | O3: Sensibilisation + 1er geste concret : gradation cohérente avec le niveau. | P3: 👍 Oui — bonne intervention pour ce palier, je ne changerais pas. | Q3: V4 · Rituels communs Dev/Ops
A4: 3 | B4: C01 | C4: Culture & Rituels | D4: La squad dispose-t-elle de rituels communs entre Dev, Ops et autres parties prenantes ? | E4: Atelier | F4: En Progrès 🟡 | G4: Moyenne | H4: Rituels naissants mais irréguliers | I4: Session formalisation des rituels : bloquer des créneaux fixes dans les agendas et co-construire un format standard | J4: — | K4: À écrire | N4: ✓ Bon | O4: Passage à la systématisation : logique de progression respectée. | P4: 👍 Oui — bonne intervention pour ce palier, je ne changerais pas. | Q4: V4 · Rituels communs Dev/Ops
A5: 4 | B5: C01 | C5: Culture & Rituels | D5: La squad dispose-t-elle de rituels communs entre Dev, Ops et autres parties prenantes ? | E5: Atelier | F5: En Progrès 🟡 | G5: Moyenne | H5: Rituels naissants mais irréguliers | I5: Atelier inclusion des parties prenantes : élargir progressivement les rituels à QA, sécu, produit | J5: — | K5: À écrire | N5: ✓ Bon | O5: Passage à la systématisation : logique de progression respectée. | P5: 👍 Oui — bonne intervention pour ce palier, je ne changerais pas. | Q5: V4 · Rituels communs Dev/Ops
A6: 5 | B6: C01 | C6: Culture & Rituels | D6: La squad dispose-t-elle de rituels communs entre Dev, Ops et autres parties prenantes ? | E6: Atelier | F6: Formalisé 🔵 | G6: Basse | H6: Rituels en place mais pas toutes les parties prenantes | I6: Session mesure de l'efficacité : co-évaluer si les blocages remontés en daily sont résolus dans la journée et ajuster le format | J6: — | K6: À écrire | N6: ✓ Bon | O6: Consolidation/mesure : clôt proprement le gradient de maturité. | P6: 👍 Oui — bonne intervention pour ce palier, je ne changerais pas. | Q6: V4 · Rituels communs Dev/Ops
A7: 6 | B7: C02 | C7: Culture & Rituels | D7: Les outils collaboratifs (Teams, Jira, Confluence) sont-ils utilisés efficacement pour réduire les frictions ? | E7: Atelier | F7: Initial 🔴 | G7: Haute | H7: Outils utilisés de façon chaotique | I7: Atelier "Notre inventaire outillage" : lister ensemble tous les outils utilisés, identifier les doublons et les usages qui se chevauchent | J7: — | K7: À écrire | N7: ✓ Bon | O7: Sensibilisation + 1er geste concret : gradation cohérente avec le niveau. | P7: 👍 Oui — bonne intervention pour ce palier, je ne changerais pas. | Q7: V4 · Outils collaboratifs
A8: 7 | B8: C02 | C8: Culture & Rituels | D8: Les outils collaboratifs (Teams, Jira, Confluence) sont-ils utilisés efficacement pour réduire les frictions ? | E8: Atelier | F8: Initial 🔴 | G8: Haute | H8: Outils utilisés de façon chaotique | I8: Session "Un outil, un usage" : co-décider des conventions — quel outil pour quel usage | J8: — | K8: À écrire | N8: ✓ Bon | O8: Sensibilisation + 1er geste concret : gradation cohérente avec le niveau. | P8: 👍 Oui — bonne intervention pour ce palier, je ne changerais pas. | Q8: V4 · Outils collaboratifs
A9: 8 | B9: C02 | C9: Culture & Rituels | D9: Les outils collaboratifs (Teams, Jira, Confluence) sont-ils utilisés efficacement pour réduire les frictions ? | E9: Atelier | F9: En Progrès 🟡 | G9: Moyenne | H9: Outils identifiés mais pas de conventions | I9: Session documentation des conventions : formaliser en 1 page les règles d'usage et les partager avec toute la squad | J9: — | K9: À écrire | N9: ✓ Bon | O9: Passage à la systématisation : logique de progression respectée. | P9: 👍 Oui — bonne intervention pour ce palier, je ne changerais pas. | Q9: V4 · Outils collaboratifs
A10: 9 | B10: C02 | C10: Culture & Rituels | D10: Les outils collaboratifs (Teams, Jira, Confluence) sont-ils utilisés efficacement pour réduire les frictions ? | E10: Atelier | F10: En Progrès 🟡 | G10: Moyenne | H10: Outils identifiés mais pas de conventions | I10: Atelier audit d'adoption : identifier qui utilise quoi et former les récalcitrants | J10: — | K10: À écrire | N10: ✓ Bon | O10: Passage à la systématisation : logique de progression respectée. | P10: 🔁 Reformuler « former les récalcitrants » → « comprendre pourquoi l'adoption coince ». L'adoption partielle = rarement mauvaise volonté, souvent inadéquation outil/workflow. | Q10: V4 · Outils collaboratifs
A11: 10 | B11: C02 | C11: Culture & Rituels | D11: Les outils collaboratifs (Teams, Jira, Confluence) sont-ils utilisés efficacement pour réduire les frictions ? | E11: Atelier | F11: Formalisé 🔵 | G11: Basse | H11: Conventions définies mais adoption partielle | I11: Session automatisation : mettre en place les notifications croisées, les liens automatiques entre outils et les templates | J11: — | K11: À écrire | N11: ✓ Bon | O11: Consolidation/mesure : clôt proprement le gradient de maturité. | P11: 👍 Oui — bonne intervention pour ce palier, je ne changerais pas. | Q11: V4 · Outils collaboratifs
A12: 11 | B12: C03 | C12: Culture & Rituels | D12: Les informations critiques (problèmes, priorités, décisions) circulent-elles rapidement et clairement à tous les membres ? | E12: Atelier | F12: Initial 🔴 | G12: Haute | H12: Les infos critiques arrivent tard ou pas du tout | I12: Atelier "Notre canal incidents" : créer ensemble un canal dédié aux incidents avec un template de communication standard | J12: — | K12: À écrire | N12: ✓ Bon | O12: Sensibilisation + 1er geste concret : gradation cohérente avec le niveau. | P12: 👍 Oui — bonne intervention pour ce palier, je ne changerais pas. | Q12: V4 · Circulation des infos critiques
A13: 12 | B13: C03 | C13: Culture & Rituels | D13: Les informations critiques (problèmes, priorités, décisions) circulent-elles rapidement et clairement à tous les membres ? | E13: Atelier | F13: Initial 🔴 | G13: Haute | H13: Les infos critiques arrivent tard ou pas du tout | I13: Session "Quand et comment communiquer ?" : co-construire un protocole de communication de crise adapté à la squad | J13: — | K13: À écrire | N13: ✓ Bon | O13: Sensibilisation + 1er geste concret : gradation cohérente avec le niveau. | P13: 👍 Oui — bonne intervention pour ce palier, je ne changerais pas. | Q13: V4 · Circulation des infos critiques
... A206: 205 | B206: X05 | C206: Sécurité | D206: Approbations invalidées après un nouveau push | E206: Sécurité | F206: — | G206: Haute | H206: — | I206: Mise en conformité sécurité : activation du setting obligatoire — Remove all approvals when commits are added | J206: — | K206: À écrire | N206: ⚠ Doublon | O206: « Reset approvals on push » est mot pour mot l'action Q02-141. Doublon exact. | P206: ➖ Item de conformité : geste correct mais redondant avec H03/Q02 (cf. colonne Verdict). | Q206: V1 · Runbook GitLab hardening

Sheet MPE
A1: # | B1: Question ID | C1: Axe | D1: Question | E1: Niveau | F1: Priorité | G1: Action | H1: Remarques MPE | I1: Ordre de production | J1: Besoin déjà couvert ? | K1: Documentation existante
A2: 1 | B2: C01 | C2: Culture & Rituels | D2: La squad dispose-t-elle de rituels communs entre Dev, Ops et autres parties prenantes ? | E2: Initial 🔴 | F2: Haute | G2: Atelier "Notre premier daily" : accompagner la squad à instaurer un daily standup de 15 min max avec Dev + Ops | H2: 🔁 Daily défendable, mais pour une squad sans aucun rituel, tenter d'abord une rétro blameless : construit le muscle de collaboration et fait remonter la douleur (le daily glisse vite vers le statut). À jauger selon la maturité relationnelle. | I2: V4 · Rituels communs Dev/Ops | J2: oui | K2: 💊 Comment intégrer les Ops aux rituels agiles
A3: 2 | B3: C01 | C3: Culture & Rituels | D3: La squad dispose-t-elle de rituels communs entre Dev, Ops et autres parties prenantes ? | E3: Initial 🔴 | F3: Haute | G3: Session "Pourquoi des rituels ?" : faire comprendre ensemble la valeur des rituels comme ciment de la collaboration | H3: ok | I3: V4 · Rituels communs Dev/Ops | J3: oui | K3: 💊 Comment intégrer les Ops aux rituels agiles
A4: 3 | B4: C01 | C4: Culture & Rituels | D4: La squad dispose-t-elle de rituels communs entre Dev, Ops et autres parties prenantes ? | E4: En Progrès 🟡 | F4: Moyenne | G4: Session formalisation des rituels : bloquer des créneaux fixes dans les agendas et co-construire un format standard | H4: ok | I4: V4 · Rituels communs Dev/Ops | J4: oui | K4: 💊 Comment intégrer les Ops aux rituels agiles
A5: 4 | B5: C01 | C5: Culture & Rituels | D5: La squad dispose-t-elle de rituels communs entre Dev, Ops et autres parties prenantes ? | E5: En Progrès 🟡 | F5: Moyenne | G5: Atelier inclusion des parties prenantes : élargir progressivement les rituels à QA, sécu, produit | H5: ok | I5: V4 · Rituels communs Dev/Ops | J5: oui | K5: 💊 Comment intégrer les Ops aux rituels agiles
A6: 5 | B6: C01 | C6: Culture & Rituels | D6: La squad dispose-t-elle de rituels communs entre Dev, Ops et autres parties prenantes ? | E6: Formalisé 🔵 | F6: Basse | G6: Session mesure de l'efficacité : co-évaluer si les blocages remontés en daily sont résolus dans la journée et ajuster le format | H6: ok | I6: V4 · Rituels communs Dev/Ops | J6: oui | K6: 💊 Comment intégrer les Ops aux rituels agiles
A7: 6 | B7: C02 | C7: Culture & Rituels | D7: Les outils collaboratifs (Teams, Jira, Confluence) sont-ils utilisés efficacement pour réduire les frictions ? | E7: Initial 🔴 | F7: Haute | G7: Atelier "Notre inventaire outillage" : lister ensemble tous les outils utilisés, identifier les doublons et les usages qui se chevauchent | H7: ok | I7: V4 · Outils collaboratifs | J7: oui
A8: 7 | B8: C02 | C8: Culture & Rituels | D8: Les outils collaboratifs (Teams, Jira, Confluence) sont-ils utilisés efficacement pour réduire les frictions ? | E8: Initial 🔴 | F8: Haute | G8: Session "Un outil, un usage" : co-décider des conventions — quel outil pour quel usage | H8: ok | I8: V4 · Outils collaboratifs | J8: oui
A9: 8 | B9: C02 | C9: Culture & Rituels | D9: Les outils collaboratifs (Teams, Jira, Confluence) sont-ils utilisés efficacement pour réduire les frictions ? | E9: En Progrès 🟡 | F9: Moyenne | G9: Session documentation des conventions : formaliser en 1 page les règles d'usage et les partager avec toute la squad | H9: ok | I9: V4 · Outils collaboratifs | J9: oui
A10: 9 | B10: C02 | C10: Culture & Rituels | D10: Les outils collaboratifs (Teams, Jira, Confluence) sont-ils utilisés efficacement pour réduire les frictions ? | E10: En Progrès 🟡 | F10: Moyenne | G10: Atelier audit d'adoption : identifier qui utilise quoi et former les récalcitrants | H10: 🔁 Reformuler « former les récalcitrants » → « comprendre pourquoi l'adoption coince ». L'adoption partielle = rarement mauvaise volonté, souvent inadéquation outil/workflow. | I10: V4 · Outils collaboratifs | J10: oui
A11: 10 | B11: C02 | C11: Culture & Rituels | D11: Les outils collaboratifs (Teams, Jira, Confluence) sont-ils utilisés efficacement pour réduire les frictions ? | E11: Formalisé 🔵 | F11: Basse | G11: Session automatisation : mettre en place les notifications croisées, les liens automatiques entre outils et les templates | H11: ok | I11: V4 · Outils collaboratifs | J11: oui
A12: 11 | B12: C03 | C12: Culture & Rituels | D12: Les informations critiques (problèmes, priorités, décisions) circulent-elles rapidement et clairement à tous les membres ? | E12: Initial 🔴 | F12: Haute | G12: Atelier "Notre canal incidents" : créer ensemble un canal dédié aux incidents avec un template de communication standard | H12: ok | I12: V4 · Circulation des infos critiques | J12: oui
A13: 12 | B13: C03 | C13: Culture & Rituels | D13: Les informations critiques (problèmes, priorités, décisions) circulent-elles rapidement et clairement à tous les membres ? | E13: Initial 🔴 | F13: Haute | G13: Session "Quand et comment communiquer ?" : co-construire un protocole de communication de crise adapté à la squad | H13: ok | I13: V4 · Circulation des infos critiques | J13: oui
A14: 13 | B14: C03 | C14: Culture & Rituels | D14: Les informations critiques (problèmes, priorités, décisions) circulent-elles rapidement et clairement à tous les membres ? | E14: En Progrès 🟡 | F14: Moyenne | G14: Session template d'incident : formaliser ensemble le format — quoi, impact, qui gère, ETA — et l'imposer comme standard | H14: ok | I14: V4 · Circulation des infos critiques | J14: oui
A15: 14 | B15: C03 | C15: Culture & Rituels | D15: Les informations critiques (problèmes, priorités, décisions) circulent-elles rapidement et clairement à tous les membres ? | E15: En Progrès 🟡 | F15: Moyenne | G15: Atelier proactivité : instaurer un point hebdo de 5 min sur les risques identifiés et les dépendances à venir | H15: ok | I15: V4 · Circulation des infos critiques | J15: oui
A16: 15 | B16: C03 | C16: Culture & Rituels | D16: Les informations critiques (problèmes, priorités, décisions) circulent-elles rapidement et clairement à tous les membres ? | E16: Formalisé 🔵 | F16: Basse | G16: Session "Angles morts" : identifier ensemble qui ne reçoit pas les infos — nouveaux, mi-temps, externes — et les inclure | H16: ok | I16: V4 · Circulation des infos critiques | J16: oui
A17: 16 | B17: C04 | C17: Culture & Rituels | D17: Les rôles et responsabilités sont-ils bien compris et partagés entre les parties ? | E17: Initial 🔴 | F17: Haute | G17: Atelier RACI : co-construire ensemble une matrice RACI sur les 10 activités clés de la squad en 30 min | H17: ✎ Reformuler — « co-construire ensemble » = pléonasme (co = ensemble). Sinon atelier RACI 30 min : excellent format. 🔁 RACI finit souvent en théâtre affiché jamais relu. Pour une squad : delegation poker (Management 3.0) ou journal de décisions d'abord — plus engageant et collant. RACI en repli. | I17: V4 · Rôles & responsabilités (RACI/delegation) | J17: oui
A18: 17 | B18: C04 | C18: Culture & Rituels | D18: Les rôles et responsabilités sont-ils bien compris et partagés entre les parties ? | E18: Initial 🔴 | F18: Haute | G18: Session "Qui décide quoi ?" : clarifier les décisions clés — qui valide un merge, qui contacte le support N3 | H18: ok | I18: V4 · Rôles & responsabilités (RACI/delegation) | J18: oui
... A21: 20 | B21: C04 | C21: Culture & Rituels | D21: Les rôles et responsabilités sont-ils bien compris et partagés entre les parties ? | E21: Formalisé 🔵 | F21: Basse | G21: Session revue trimestrielle : instaurer une revue de la RACI à chaque changement d'équipe ou de périmètre | H21: ok | I21: V4 · Rôles & responsabilités (RACI/delegation) | J21: oui
A22: 21 | B22: C05 | C22: Culture & Rituels | D22: Le backlog intègre-t-il les besoins techniques et opérationnels ? (→ User Stories Dev, Sec ET Ops) | E22: Initial 🔴 | F22: Haute | G22: Atelier "Notre backlog est-il complet ?" : faire émerger ce qui manque côté technique, sécu et ops | H22: ok | I22: V5 · Backlog technique & ops | J22: oui | K22: 💊 Users Stories Dev + Ops
A23: 22 | B23: C05 | C23: Culture & Rituels | D23: Le backlog intègre-t-il les besoins techniques et opérationnels ? (→ User Stories Dev, Sec ET Ops) | E23: Initial 🔴 | F23: Haute | G23: Session négociation avec le PO : accompagner la squad à défendre un quota minimum de 20% pour le technique | H23: ok | I23: V5 · Backlog technique & ops | J23: oui | K23: 💊 Users Stories Dev + Ops
A24: 23 | B24: C05 | C24: Culture & Rituels | D24: Le backlog intègre-t-il les besoins techniques et opérationnels ? (→ User Stories Dev, Sec ET Ops) | E24: En Progrès 🟡 | F24: Moyenne | G24: Session quota technique : formaliser un engagement de 20% minimum par sprint, non négociable | H24: 🔁 Quota fixe « non négociable » = dogmatique, se retourne contre l'équipe. Relier l'investissement technique au RISQUE observé (incidents, lead time, CVE) pour que le PO arbitre sur des faits. Le quota comme repère, pas comme règle. | I24: V5 · Backlog technique & ops | J24: oui | K24: 💊 Users Stories Dev + Ops
A25: 24 | B25: C05 | C25: Culture & Rituels | D25: Le backlog intègre-t-il les besoins techniques et opérationnels ? (→ User Stories Dev, Sec ET Ops) | E25: En Progrès 🟡 | F25: Moyenne | G25: Atelier "US techniques bien rédigées" : apprendre à écrire des US techniques avec de la valeur visible pour le PO | H25: ok | I25: V5 · Backlog technique & ops | J25: oui | K25: 💊 Users Stories Dev + Ops
A26: 25 | B26: C05 | C26: Culture & Rituels | D26: Le backlog intègre-t-il les besoins techniques et opérationnels ? (→ User Stories Dev, Sec ET Ops) | E26: Formalisé 🔵 | F26: Basse | G26: Session élargissement du backlog : intégrer systématiquement les sujets sécu (scan, dépendances) et ops (monitoring, alerting) | H26: ok | I26: V5 · Backlog technique & ops | J26: oui | K26: 💊 Users Stories Dev + Ops
A27: 26 | B27: C06 | C27: Culture & Rituels | D27: Les dépendances avec d'autres squads sont-elles anticipées et coordonnées sans blocage ? | E27: Initial 🔴 | F27: Haute | G27: Atelier cartographie des dépendances : identifier ensemble toutes les dépendances externes et les rendre visibles | H27: ok | I27: V5 · Dépendances inter-squads | J27: oui
A28: 27 | B28: C06 | C28: Culture & Rituels | D28: Les dépendances avec d'autres squads sont-elles anticipées et coordonnées sans blocage ? | E28: Initial 🔴 | F28: Haute | G28: Session synchro inter-squads : instaurer un point bimensuel de 15 min avec les squads dont on dépend | H28: ok | I28: V5 · Dépendances inter-squads | J28: oui
A29: 28 | B29: C06 | C29: Culture & Rituels | D29: Les dépendances avec d'autres squads sont-elles anticipées et coordonnées sans blocage ? | E29: En Progrès 🟡 | F29: Moyenne | G29: Session intégration au sprint planning : pour chaque US, identifier "de qui dépend-on ?" et traiter les flous comme des risques | H29: ok | I29: V5 · Dépendances inter-squads | J29: oui
A30: 29 | B30: C06 | C30: Culture & Rituels | D30: Les dépendances avec d'autres squads sont-elles anticipées et coordonnées sans blocage ? | E30: En Progrès 🟡 | F30: Moyenne | G30: Atelier SLA de réponse : négocier ensemble des engagements de réponse avec les squads dépendantes | H30: 🔁 SLA inter-squads sans autorité = rarement tenus. Préférer working agreements + dépendances visibles sur board partagé (PI planning allégé) à un SLA lettre morte. | I30: V5 · Dépendances inter-squads | J30: oui
A31: 30 | B31: C06 | C31: Culture & Rituels | D31: Les dépendances avec d'autres squads sont-elles anticipées et coordonnées sans blocage ? | E31: Formalisé 🔵 | F31: Basse | G31: Session contrats d'interface : documenter ensemble les interfaces exposées pour que les autres squads puissent s'y fier | H31: ok | I31: V5 · Dépendances inter-squads | J31: oui
A32: 31 | B32: C07 | C32: Culture & Rituels | D32: Avez-vous instauré des DevOps Reviews régulières ? (avec actions concrètes prises et réalisées) | E32: Initial 🔴 | F32: Haute | G32: Accompagnement DevOps Review : co-construire le format, le rythme et les indicateurs de la première DevOps Review | H32: ok | I32: V1 · Canevas DevOps Review | J32: oui
A33: 32 | B33: C07 | C33: Culture & Rituels | D33: Avez-vous instauré des DevOps Reviews régulières ? (avec actions concrètes prises et réalisées) | E33: Initial 🔴 | F33: Haute | G33: Session "Notre première DevOps Review" : animer ensemble la première session et poser 3 actions concrètes pour le mois suivant | H33: ok | I33: V1 · Canevas DevOps Review | J33: oui
A34: 33 | B34: C07 | C34: Culture & Rituels | D34: Avez-vous instauré des DevOps Reviews régulières ? (avec actions concrètes prises et réalisées) | E34: En Progrès 🟡 | F34: Moyenne | G34: Session formalisation du template : métriques clés, incidents marquants, actions passées, prochaines actions | H34: ok | I34: V1 · Canevas DevOps Review | J34: oui
A35: 34 | B35: C07 | C35: Culture & Rituels | D35: Avez-vous instauré des DevOps Reviews régulières ? (avec actions concrètes prises et réalisées) | E35: En Progrès 🟡 | F35: Moyenne | G35: Atelier suivi des actions : chaque action a un responsable et une deadline — on commence à la prochaine session | H35: ok | I35: V1 · Canevas DevOps Review | J35: oui
A36: 35 | B36: C07 | C36: Culture & Rituels | D36: Avez-vous instauré des DevOps Reviews régulières ? (avec actions concrètes prises et réalisées) | E36: Formalisé 🔵 | F36: Basse | G36: Session ouverture au management : préparer ensemble une DevOps Review pour le management — métriques, progrès, blocages | H36: ok | I36: V1 · Canevas DevOps Review | J36: oui
A37: 36 | B37: C08 | C37: Culture & Rituels | D37: Vous sentez-vous libre de partager des idées, signaler des problèmes ou admettre des erreurs sans crainte de répercussions ? | E37: Initial 🔴 | F37: Haute | G37: Atelier blameless culture : introduire le post-mortem sans blame sur un incident récent — zéro nom, que le système | H37: ok | I37: V1 · Atelier Blameless / Sécurité psy | J37: oui | K37: 💊 Post Mortem ; 🖼️ Template - Post Mortem
A38: 37 | B38: C08 | C38: Culture & Rituels | D38: Vous sentez-vous libre de partager des idées, signaler des problèmes ou admettre des erreurs sans crainte de répercussions ? | E38: Initial 🔴 | F38: Haute | G38: Session "On parle du système, jamais des gens" : ancrer la règle et la pratiquer ensemble sur un cas concret | H38: ok | I38: V1 · Atelier Blameless / Sécurité psy | J38: oui | K38: 💊 Post Mortem ; 🖼️ Template - Post Mortem
A39: 38 | B39: C08 | C39: Culture & Rituels | D39: Vous sentez-vous libre de partager des idées, signaler des problèmes ou admettre des erreurs sans crainte de répercussions ? | E39: En Progrès 🟡 | F39: Moyenne | G39: Atelier valorisation publique : apprendre à remercier explicitement celui qui remonte un problème | H39: ok | I39: V1 · Atelier Blameless / Sécurité psy | J39: oui | K39: 💊 Post Mortem ; 🖼️ Template - Post Mortem
A40: 39 | B40: C08 | C40: Culture & Rituels | D40: Vous sentez-vous libre de partager des idées, signaler des problèmes ou admettre des erreurs sans crainte de répercussions ? | E40: En Progrès 🟡 | F40: Moyenne | G40: Session rétrospective anonyme : utiliser des formats anonymes pour vérifier que tout le monde se sent vraiment libre | H40: 🔁 Rétro anonyme = béquille de diagnostic utile, mais pas un régime permanent (signale une sécurité psy basse). À utiliser temporairement, viser le non-anonyme. | I40: V1 · Atelier Blameless / Sécurité psy | J40: oui | K40: 💊 Post Mortem ; 🖼️ Template - Post Mortem
A41: 40 | B41: C08 | C41: Culture & Rituels | D41: Vous sentez-vous libre de partager des idées, signaler des problèmes ou admettre des erreurs sans crainte de répercussions ? | E41: Formalisé 🔵 | F41: Basse | G41: Session extension de la sécurité psychologique : travailler la posture dans les interactions inter-squads et avec le management | H41: ok | I41: V1 · Atelier Blameless / Sécurité psy | J41: oui | K41: 💊 Post Mortem ; 🖼️ Template - Post Mortem
A42: 41 | B42: C09 | C42: Culture & Rituels | D42: La squad partage-t-elle ses retours d'expérience avec d'autres équipes internes ou externes ? | E42: Initial 🔴 | F42: Haute | G42: Session "Notre premier lightning talk" : identifier un sujet maîtrisé et préparer ensemble un talk de 10 min pour une squad voisine | H42: ok | I42: V5 · Partage des REX | J42: oui | K42: 💊 Post Mortem
...

Sheet ateliers
A1: # | B1: Vague | C1: Support à produire | D1: Description | E1: Type | F1: Lignes couvertes | G1: Questions | H1: Axe(s) | I1: À retravailler d'abord | J1: Statut | L1: Définition des types de support
A2: 1 | B2: V1 | C2: Canevas DevOps Review | D2: Trame d’animation de la DevOps Review : format, rythme, indicateurs suivis et fil des actions. But : installer le rituel récurrent où la squad pilote sa progression et où tous les autres chantiers remontent et se maintiennent. | E2: Canevas | F2: 5 | G2: C07 | H2: Culture & Rituels | I2: — | J2: À produire | L2: Canevas | M2: Trame réutilisable et structurante pour un rituel récurrent (format, déroulé, indicateurs). La squad la rejoue à chaque occurrence. Ex. DevOps Review.
A3: 2 | B3: V1 | C3: Atelier Blameless / Sécurité psy | D3: Post-mortem sans blâme sur un incident réel + ancrage de la règle « on parle du système, jamais des gens ». But : créer la sécurité psychologique sans laquelle aucune rétro, diagnostic ou remontée honnête ne tient. | E3: Atelier | F3: 5 | G3: C08 | H3: Culture & Rituels | I3: Oui | J3: À produire | L3: Atelier | M3: Session animée ponctuelle (~1 h) de montée en compétence collective / co-construction sur un sujet, avec objectif, déroulé et livrable. Format majoritaire du catalogue.
A4: 3 | B4: V1 | C4: Runbook GitLab hardening | D4: Pas-à-pas de configuration des protections GitLab : branche protégée, force push interdit, règles d’approbation (2 approbateurs, auteur/committers exclus, reset on push), pipelines-must-succeed. But : mettre les repos en conformité bancaire en un seul geste outillé. | E4: Runbook | F4: 20 | G4: H03, Q02, Q05, S04, X01, X02, X03, X04, X05 | H4: Hygiène & Gouvernance, Processus Merge, Stabilité Pipeline, Sécurité | I4: — | J4: À produire | L4: Runbook | M4: Procédure opérationnelle courte et actionnable : le pourquoi + le pas-à-pas de configuration pour un geste technique ou de conformité. Pas un atelier. Ex. hardening GitLab.
A5: 4 | B5: V2 | C5: Kit diagnostic & miroir | D5: Gabarit d’animation réutilisable pour les sessions de prise de conscience : cartographie de l’existant, visualisation des données, restitution « dans le miroir ». But : un format unique servant les 3 diagnostics préalables et tous les ateliers de prise de conscience. | E5: Kit | F5: 3 | G5: H01, Q01, R01 | H5: Hygiène & Gouvernance, Processus Merge, Résilience & Bus Factor | I5: — | J5: À produire | L5: Kit | M5: Ensemble de gabarits et supports d’animation réutilisables, transverses à plusieurs questions, mutualisés pour écrire une fois et servir partout. Ex. kit diagnostic, kit slicing.
A6: 5 | B6: V2 | C6: Kit slicing / découpage | D6: Méthode et exercices de découpage : feature slicing, un seul changement logique par MR, petits incréments quotidiens. But : socle commun pour réduire la taille des MR et fluidifier le flux et la régularité des commits. | E6: Kit | F6: 8 | G6: D01, Q04, R04 | H6: Processus Merge, Résilience & Bus Factor, Toolchain CI/CD | I6: Oui | J6: À produire
A7: 6 | B7: V2 | C7: CI : premier pipeline & .gitlab-ci.yml | D7: Création du premier .gitlab-ci.yml versionné et du premier déclencheur automatique sur merge. But : poser le prérequis technique sans lequel aucun autre chantier CI/CD n’est possible. | E7: Atelier | F7: 9 | G7: D01, P05 | H7: Pratiques DevOps, Toolchain CI/CD | I7: Oui | J7: À produire
A8: 7 | B8: V2 | C8: Performance pipeline (cache, parallélisation) | D8: Mesure de la durée par stage puis optimisation : cache des dépendances, parallélisation, images Docker légères. But : ramener le pipeline sous 15 min et créer l’adhésion par un gain visible. | E8: Atelier | F8: 6 | G8: D05 | H8: Toolchain CI/CD | I8: — | J8: À produire
A9: 8 | B9: V3 | C9: Flux des MR (délais & tri) | D9: Diagnostic du cycle de vie d’une MR, SLA de review/merge, rappels automatiques et tri des MR zombies. But : raccourcir le temps d’attente et désengorger le flux de revue. | E9: Atelier | F9: 10 | G9: H05, Q01 | H9: Hygiène & Gouvernance, Processus Merge | I9: — | J9: À produire
A10: 9 | B10: V3 | C10: Stabilité du pipeline (échecs) | D10: Autopsie des échecs, stabilisation de la cause dominante, retry ciblés, suivi du taux de succès. But : rendre le pipeline fiable et redonner confiance dans le vert. | E10: Atelier | F10: 6 | G10: D02 | H10: Toolchain CI/CD | I10: Oui | J10: À produire
A11: 10 | B11: V3 | C11: Pipeline complet : test / lint / sécu | D11: Ajout progressif des stages test, lint et sécurité (SAST, scan de dépendances) avec quality gates. But : passer d’un pipeline « build seul » à un pipeline qui protège réellement. | E11: Atelier | F11: 5 | G11: P04 | H11: Pratiques DevOps | I11: — | J11: À produire
A12: 11 | B12: V3 | C12: Déploiement via main & branches | D12: Restriction des déploiements à la branche principale, gouvernance et nommage des branches, gestion des exceptions. But : fiabiliser et tracer l’origine des déploiements. | E12: Atelier | F12: 5 | G12: D03 | H12: Toolchain CI/CD | I12: — | J12: À produire
A13: 12 | B13: V3 | C13: Hygiène des branches | D13: Suppression automatique après merge, nettoyage de l’existant, conventions de nommage, alertes branches stale. But : garder un repo lisible, sans branches mortes. | E13: Atelier | F13: 5 | G13: H01 | H13: Hygiène & Gouvernance | I13: — | J13: À produire
A14: 13 | B14: V3 | C14: Fichiers essentiels du repo | D14: Mise en place et enrichissement de README, .gitignore, CHANGELOG, CONTRIBUTING. But : donner à chaque repo une identité et faciliter l’onboarding. | E14: Atelier | F14: 5 | G14: H04 | H14: Hygiène & Gouvernance | I14: — | J14: À produire
A15: 14 | B15: V4 | C15: Feature flags (mise en place) | D15: Concept du découplage déploiement/activation, premier flag, outillage, targeting. But : déployer souvent sans peur en activant les fonctionnalités à la demande. | E15: Atelier | F15: 7 | G15: D01, P01 | H15: Pratiques DevOps, Toolchain CI/CD | I15: Oui | J15: À produire
A16: 15 | B16: V4 | C16: Feature flags (nettoyage) | D16: Inventaire des flags, suppression des zombies, dates d’expiration, automatisation du nettoyage. But : éviter l’accumulation de dette de flags. | E16: Atelier | F16: 5 | G16: P02 | H16: Pratiques DevOps | I16: — | J16: À produire
A17: 16 | B17: V4 | C17: Versions de dépendances fixées | D17: Suppression des SNAPSHOT/LATEST/ranges, fixation des versions, scan de vulnérabilités. But : garantir des builds reproductibles et maîtriser le risque supply chain. | E17: Atelier | F17: 4 | G17: P03 | H17: Pratiques DevOps | I17: — | J17: À produire
... A36: 35 | B36: V5 | C36: Maîtrise du calendrier de livraison | D36: Inventaire des contraintes, négociation de SLA externes, automatisation des validations. But : reprendre la main sur le calendrier de livraison hors frozen zone. | E36: Atelier | F36: 5 | G36: C10 | H36: Culture & Rituels | I36: — | J36: À produire
C37: TOTAL | F37: =SUM(F2:F36) -> 205

Sheet 📊 Par axe
A1: Synthèse par axe d'évaluation
A3: Axe | B3: Total actions | C3: Niveau 1 (Initial) | D3: Niveau 2 (Progrès) | E3: Niveau 3 (Formalisé) | F3: % Avancement (écrits / total)
A4: Culture & Rituels | B4: =COUNTIF('🎯 205 Actions'!C2:C206,A4) -> 50 | C4: =COUNTIFS('🎯 205 Actions'!C2:C206,A4,'🎯 205 Actions'!F2:F206,"Initial 🔴") -> 20 | D4: =COUNTIFS('🎯 205 Actions'!C2:C206,A4,'🎯 205 Actions'!F2:F206,"En Progrès 🟡") -> 20 | E4: =COUNTIFS('🎯 205 Actions'!C2:C206,A4,'🎯 205 Actions'!F2:F206,"Formalisé 🔵") -> 10 | F4: =IFERROR(COUNTIFS('🎯 205 Actions'!C2:C206,A4,'🎯 205 Actions'!K2:K206,"Écrit")/B4,0) -> 0
A5: Toolchain CI/CD | B5: =COUNTIF('🎯 205 Actions'!C2:C206,A5) -> 28 | C5: =COUNTIFS('🎯 205 Actions'!C2:C206,A5,'🎯 205 Actions'!F2:F206,"Initial 🔴") -> 10 | D5: =COUNTIFS('🎯 205 Actions'!C2:C206,A5,'🎯 205 Actions'!F2:F206,"En Progrès 🟡") -> 10 | E5: =COUNTIFS('🎯 205 Actions'!C2:C206,A5,'🎯 205 Actions'!F2:F206,"Formalisé 🔵") -> 8 | F5: =IFERROR(COUNTIFS('🎯 205 Actions'!C2:C206,A5,'🎯 205 Actions'!K2:K206,"Écrit")/B5,0) -> 0
A6: Hygiène & Gouvernance | B6: =COUNTIF('🎯 205 Actions'!C2:C206,A6) -> 26 | C6: =COUNTIFS('🎯 205 Actions'!C2:C206,A6,'🎯 205 Actions'!F2:F206,"Initial 🔴") -> 10 | D6: =COUNTIFS('🎯 205 Actions'!C2:C206,A6,'🎯 205 Actions'!F2:F206,"En Progrès 🟡") -> 9 | E6: =COUNTIFS('🎯 205 Actions'!C2:C206,A6,'🎯 205 Actions'!F2:F206,"Formalisé 🔵") -> 6 | F6: =IFERROR(COUNTIFS('🎯 205 Actions'!C2:C206,A6,'🎯 205 Actions'!K2:K206,"Écrit")/B6,0) -> 0
A7: Pratiques DevOps | B7: =COUNTIF('🎯 205 Actions'!C2:C206,A7) -> 26 | C7: =COUNTIFS('🎯 205 Actions'!C2:C206,A7,'🎯 205 Actions'!F2:F206,"Initial 🔴") -> 10 | D7: =COUNTIFS('🎯 205 Actions'!C2:C206,A7,'🎯 205 Actions'!F2:F206,"En Progrès 🟡") -> 10 | E7: =COUNTIFS('🎯 205 Actions'!C2:C206,A7,'🎯 205 Actions'!F2:F206,"Formalisé 🔵") -> 6 | F7: =IFERROR(COUNTIFS('🎯 205 Actions'!C2:C206,A7,'🎯 205 Actions'!K2:K206,"Écrit")/B7,0) -> 0
A8: Processus Merge | B8: =COUNTIF('🎯 205 Actions'!C2:C206,A8) -> 27 | C8: =COUNTIFS('🎯 205 Actions'!C2:C206,A8,'🎯 205 Actions'!F2:F206,"Initial 🔴") -> 10 | D8: =COUNTIFS('🎯 205 Actions'!C2:C206,A8,'🎯 205 Actions'!F2:F206,"En Progrès 🟡") -> 10 | E8: =COUNTIFS('🎯 205 Actions'!C2:C206,A8,'🎯 205 Actions'!F2:F206,"Formalisé 🔵") -> 6 | F8: =IFERROR(COUNTIFS('🎯 205 Actions'!C2:C206,A8,'🎯 205 Actions'!K2:K206,"Écrit")/B8,0) -> 0
A9: Résilience & Bus Factor | B9: =COUNTIF('🎯 205 Actions'!C2:C206,A9) -> 21 | C9: =COUNTIFS('🎯 205 Actions'!C2:C206,A9,'🎯 205 Actions'!F2:F206,"Initial 🔴") -> 8 | D9: =COUNTIFS('🎯 205 Actions'!C2:C206,A9,'🎯 205 Actions'!F2:F206,"En Progrès 🟡") -> 8 | E9: =COUNTIFS('🎯 205 Actions'!C2:C206,A9,'🎯 205 Actions'!F2:F206,"Formalisé 🔵") -> 4 | F9: =IFERROR(COUNTIFS('🎯 205 Actions'!C2:C206,A9,'🎯 205 Actions'!K2:K206,"Écrit")/B9,0) -> 0
A10: Stabilité Pipeline | B10: =COUNTIF('🎯 205 Actions'!C2:C206,A10) -> 22 | C10: =COUNTIFS('🎯 205 Actions'!C2:C206,A10,'🎯 205 Actions'!F2:F206,"Initial 🔴") -> 10 | D10: =COUNTIFS('🎯 205 Actions'!C2:C206,A10,'🎯 205 Actions'!F2:F206,"En Progrès 🟡") -> 8 | E10: =COUNTIFS('🎯 205 Actions'!C2:C206,A10,'🎯 205 Actions'!F2:F206,"Formalisé 🔵") -> 4 | F10: =IFERROR(COUNTIFS('🎯 205 Actions'!C2:C206,A10,'🎯 205 Actions'!K2:K206,"Écrit")/B10,0) -> 0
A11: Sécurité | B11: =COUNTIF('🎯 205 Actions'!C2:C206,A11) -> 5 | C11: =COUNTIFS('🎯 205 Actions'!C2:C206,A11,'🎯 205 Actions'!F2:F206,"Initial 🔴") -> 0 | D11: =COUNTIFS('🎯 205 Actions'!C2:C206,A11,'🎯 205 Actions'!F2:F206,"En Progrès 🟡") -> 0 | E11: =COUNTIFS('🎯 205 Actions'!C2:C206,A11,'🎯 205 Actions'!F2:F206,"Formalisé 🔵") -> 0 | F11: =IFERROR(COUNTIFS('🎯 205 Actions'!C2:C206,A11,'🎯 205 Actions'!K2:K206,"Écrit")/B11,0) -> 0
A12: TOTAL | B12: =SUM(B4:B11) -> 205 | C12: =SUM(C4:C11) -> 78 | D12: =SUM(D4:D11) -> 75 | E12: =SUM(E4:E11) -> 44 | F12: =IFERROR(COUNTIF('🎯 205 Actions'!K2:K206,"Écrit")/B12,0) -> 0

Sheet 🚦 Par priorité
A1: Synthèse par priorité
A3: Vue d'ensemble
A4: Priorité | B4: Nb actions | C4: Écrits | D4: % Avancement
A5: Haute | B5: =COUNTIF('🎯 205 Actions'!G2:G206,A5) -> 83 | C5: =COUNTIFS('🎯 205 Actions'!G2:G206,A5,'🎯 205 Actions'!K2:K206,"Écrit") -> 0 | D5: =IFERROR(C5/B5,0) -> 0
A6: Moyenne | B6: =COUNTIF('🎯 205 Actions'!G2:G206,A6) -> 75 | C6: =COUNTIFS('🎯 205 Actions'!G2:G206,A6,'🎯 205 Actions'!K2:K206,"Écrit") -> 0 | D6: =IFERROR(C6/B6,0) -> 0
A7: Basse | B7: =COUNTIF('🎯 205 Actions'!G2:G206,A7) -> 44 | C7: =COUNTIFS('🎯 205 Actions'!G2:G206,A7,'🎯 205 Actions'!K2:K206,"Écrit") -> 0 | D7: =IFERROR(C7/B7,0) -> 0
A8: Préalable | B8: =COUNTIF('🎯 205 Actions'!G2:G206,A8) -> 3 | C8: =COUNTIFS('🎯 205 Actions'!G2:G206,A8,'🎯 205 Actions'!K2:K206,"Écrit") -> 0 | D8: =IFERROR(C8/B8,0) -> 0
A11: Stratégie d'écriture recommandée
A12: Phase 1 (Lancement) | B12: Top 30-50 actions Haute priorité (Niveau 1) — les plus déclenchées chez LCL
A13: Phase 2 (Stabilisation) | B13: Compléter toutes les Hautes + démarrer les Moyennes (~80-100 ateliers cumulés)
A14: Phase 3 (Couverture) | B14: Compléter Moyennes + Basses — open source / contributions externes possibles
A15: Diagnostics | B15: À écrire en parallèle des Phase 1 — préalables à plusieurs actions

Sheet 📝 Backlog Phase 1
A1: Backlog Phase 1 — Top 30-50 actions à écrire en priorité
A2: À remplir avec les actions les plus déclenchées dans les évaluations LCL (data extraite du DevOps Hub).
A4: Rang | B4: # Action | C4: Question ID | D4: Axe | E4: Action | F4: Fréquence LCL (à remplir)
A5: 1 | B5: 1 | C5: C01 | D5: Culture & Rituels | E5: Atelier "Notre premier daily" : accompagner la squad à instaurer un daily standup de 15 min max avec Dev + Ops
A6: 2 | B6: 2 | C6: C01 | D6: Culture & Rituels | E6: Session "Pourquoi des rituels ?" : faire comprendre ensemble la valeur des rituels comme ciment de la collaboration
A7: 3 | B7: 6 | C7: C02 | D7: Culture & Rituels | E7: Atelier "Notre inventaire outillage" : lister ensemble tous les outils utilisés, identifier les doublons et les usages qui se chevauchent
A8: 4 | B8: 7 | C8: C02 | D8: Culture & Rituels | E8: Session "Un outil, un usage" : co-décider des conventions — quel outil pour quel usage
A9: 5 | B9: 11 | C9: C03 | D9: Culture & Rituels | E9: Atelier "Notre canal incidents" : créer ensemble un canal dédié aux incidents avec un template de communication standard
A10: 6 | B10: 12 | C10: C03 | D10: Culture & Rituels | E10: Session "Quand et comment communiquer ?" : co-construire un protocole de communication de crise adapté à la squad
A11: 7 | B11: 16 | C11: C04 | D11: Culture & Rituels | E11: Atelier RACI : co-construire ensemble une matrice RACI sur les 10 activités clés de la squad en 30 min
A12: 8 | B12: 17 | C12: C04 | D12: Culture & Rituels | E12: Session "Qui décide quoi ?" : clarifier les décisions clés — qui valide un merge, qui contacte le support N3
A13: 9 | B13: 21 | C13: C05 | D13: Culture & Rituels | E13: Atelier "Notre backlog est-il complet ?" : faire émerger ce qui manque côté technique, sécu et ops
A14: 10 | B14: 22 | C14: C05 | D14: Culture & Rituels | E14: Session négociation avec le PO : accompagner la squad à défendre un quota minimum de 20% pour le technique
A15: 11 | B15: 26 | C15: C06 | D15: Culture & Rituels | E15: Atelier cartographie des dépendances : identifier ensemble toutes les dépendances externes et les rendre visibles
A16: 12 | B16: 27 | C16: C06 | D16: Culture & Rituels | E16: Session synchro inter-squads : instaurer un point bimensuel de 15 min avec les squads dont on dépend
... A54: 50 | B54: 127 | C54: P05 | D54: Pratiques DevOps | E54: Session création du premier fichier : créer ensemble un .gitlab-ci.yml minimal avec un stage build et le commiter
